[32mINFO    [0m juju.model:__init__.py:3254 Waiting for model:
  vault-k8s/0 [idle] active: 
  vault-k8s/1 [idle] active: 
  vault-k8s/2 [idle] active: 
[32mINFO    [0m juju.model:__init__.py:3254 Waiting for model:
  s3-integrator/0 [idle] active:
[32mINFO    [0m pytest_operator.plugin:plugin.py:937 Model status:

Model             Controller                Cloud/Region        Version  SLA          Timestamp
test-backup-nkk8  github-pr-1523e-microk8s  microk8s/localhost  3.6.8    unsupported  02:44:58Z

App            Version                Status  Scale  Charm          Channel         Rev  Address         Exposed  Message
minio          res:oci-image@220b31a  active      1  minio          ckf-1.9/stable  383  10.152.183.133  no       
s3-integrator                         active      1  s3-integrator  latest/stable   145  10.152.183.234  no       
vault-k8s                             active      3  vault-k8s                        0  10.152.183.120  no       

Unit              Workload  Agent  Address      Ports          Message
minio/0*          active    idle   10.1.63.220  9000-9001/TCP  
s3-integrator/0*  active    idle   10.1.63.213                 
vault-k8s/0*      active    idle   10.1.63.210                 
vault-k8s/1       active    idle   10.1.63.218                 
vault-k8s/2       active    idle   10.1.63.217                 

[32mINFO    [0m pytest_operator.plugin:plugin.py:943 Juju error logs:

unit-vault-k8s-2: 02:42:20 ERROR unit.vault-k8s/2.juju-log [vault_client] Error while checking Vault health status: HTTPSConnectionPool(host='vault-k8s-2.vault-k8s-endpoints.test-backup-nkk8.svc.cluster.local', port=8200): Max retries exceeded with url: /v1/sys/health (Caused by NewConnectionError('<urllib3.connection.HTTPSConnection object at 0x7fd15c067500>: Failed to establish a new connection: [Errno 111] Connection refused'))
unit-vault-k8s-1: 02:42:20 ERROR unit.vault-k8s/1.juju-log [vault_client] Error while checking Vault health status: HTTPSConnectionPool(host='vault-k8s-1.vault-k8s-endpoints.test-backup-nkk8.svc.cluster.local', port=8200): Max retries exceeded with url: /v1/sys/health (Caused by NewConnectionError('<urllib3.connection.HTTPSConnection object at 0x7f196766acf0>: Failed to establish a new connection: [Errno 111] Connection refused'))
unit-vault-k8s-1: 02:42:22 ERROR unit.vault-k8s/1.juju-log [vault_client] Error while checking Vault health status: HTTPSConnectionPool(host='vault-k8s-1.vault-k8s-endpoints.test-backup-nkk8.svc.cluster.local', port=8200): Max retries exceeded with url: /v1/sys/health (Caused by NewConnectionError('<urllib3.connection.HTTPSConnection object at 0x7f8597b36f30>: Failed to establish a new connection: [Errno 111] Connection refused'))
unit-vault-k8s-2: 02:42:22 ERROR unit.vault-k8s/2.juju-log [vault_client] Error while checking Vault health status: HTTPSConnectionPool(host='vault-k8s-2.vault-k8s-endpoints.test-backup-nkk8.svc.cluster.local', port=8200): Max retries exceeded with url: /v1/sys/health (Caused by NewConnectionError('<urllib3.connection.HTTPSConnection object at 0x7f8fe44e6f30>: Failed to establish a new connection: [Errno 111] Connection refused'))
unit-vault-k8s-1: 02:42:23 ERROR unit.vault-k8s/1.juju-log vault-peers:0: [vault_client] Error while checking Vault health status: HTTPSConnectionPool(host='vault-k8s-1.vault-k8s-endpoints.test-backup-nkk8.svc.cluster.local', port=8200): Max retries exceeded with url: /v1/sys/health (Caused by NewConnectionError('<urllib3.connection.HTTPSConnection object at 0x7fdcf5402840>: Failed to establish a new connection: [Errno 111] Connection refused'))
unit-vault-k8s-2: 02:42:23 ERROR unit.vault-k8s/2.juju-log vault-peers:0: [vault_client] Error while checking Vault health status: HTTPSConnectionPool(host='vault-k8s-2.vault-k8s-endpoints.test-backup-nkk8.svc.cluster.local', port=8200): Max retries exceeded with url: /v1/sys/health (Caused by NewConnectionError('<urllib3.connection.HTTPSConnection object at 0x7f25d05ff110>: Failed to establish a new connection: [Errno 111] Connection refused'))

[32mINFO    [0m pytest_operator.plugin:plugin.py:1049 Resetting model test-backup-nkk8...
[32mINFO    [0m pytest_operator.plugin:plugin.py:1038    Destroying applications vault-k8s
[32mINFO    [0m pytest_operator.plugin:plugin.py:1038    Destroying applications s3-integrator
[32mINFO    [0m pytest_operator.plugin:plugin.py:1038    Destroying applications minio
[32mINFO    [0m pytest_operator.plugin:plugin.py:1054 Not waiting on reset to complete.
[32mINFO    [0m pytest_operator.plugin:plugin.py:1025 Forgetting model main...