[32mINFO    [0m juju.model:__init__.py:2301 Deploying local:vault-kv-requirer-1
[32mINFO    [0m juju.model:__init__.py:3254 Waiting for model:
  vault-kv-requirer-b/0 [allocating] waiting: installing agent
[32mINFO    [0m juju.model:__init__.py:3254 Waiting for model:
  vault-kv-requirer-b/0 [idle] active: 
[32mINFO    [0m juju.model:__init__.py:3254 Waiting for model:
  vault-k8s/0 [idle] active: 
  vault-k8s/1 [idle] active: 
  vault-k8s/2 [idle] active: 
  vault-kv-requirer-b/0 [idle] active: 
[32mINFO    [0m juju.model:__init__.py:3254 Waiting for model:
  vault-kv-requirer-b/0 [idle] active:
[32mINFO    [0m pytest_operator.plugin:plugin.py:937 Model status:

Model         Controller                Cloud/Region        Version  SLA          Timestamp
test-kv-tucn  github-pr-1523e-microk8s  microk8s/localhost  3.6.8    unsupported  02:46:16Z

App                  Version  Status  Scale  Charm              Channel  Rev  Address         Exposed  Message
vault-k8s                     active      3  vault-k8s                     0  10.152.183.251  no       
vault-kv-requirer-a           active      1  vault-kv-requirer             0  10.152.183.96   no       
vault-kv-requirer-b           active      1  vault-kv-requirer             1  10.152.183.45   no       

Unit                    Workload  Agent  Address      Ports  Message
vault-k8s/0*            active    idle   10.1.63.212         
vault-k8s/1             active    idle   10.1.63.216         
vault-k8s/2             active    idle   10.1.63.217         
vault-kv-requirer-a/0*  active    idle   10.1.63.219         
vault-kv-requirer-b/0*  active    idle   10.1.63.221         

[32mINFO    [0m pytest_operator.plugin:plugin.py:943 Juju error logs:

unit-vault-k8s-1: 02:42:22 ERROR unit.vault-k8s/1.juju-log [vault_client] Error while checking Vault health status: HTTPSConnectionPool(host='vault-k8s-1.vault-k8s-endpoints.test-kv-tucn.svc.cluster.local', port=8200): Max retries exceeded with url: /v1/sys/health (Caused by NewConnectionError('<urllib3.connection.HTTPSConnection object at 0x7fe069953590>: Failed to establish a new connection: [Errno 111] Connection refused'))
unit-vault-k8s-2: 02:42:23 ERROR unit.vault-k8s/2.juju-log [vault_client] Error while checking Vault health status: HTTPSConnectionPool(host='vault-k8s-2.vault-k8s-endpoints.test-kv-tucn.svc.cluster.local', port=8200): Max retries exceeded with url: /v1/sys/health (Caused by NewConnectionError('<urllib3.connection.HTTPSConnection object at 0x7f0e68d57620>: Failed to establish a new connection: [Errno 111] Connection refused'))
unit-vault-k8s-1: 02:42:24 ERROR unit.vault-k8s/1.juju-log [vault_client] Error while checking Vault health status: HTTPSConnectionPool(host='vault-k8s-1.vault-k8s-endpoints.test-kv-tucn.svc.cluster.local', port=8200): Max retries exceeded with url: /v1/sys/health (Caused by NewConnectionError('<urllib3.connection.HTTPSConnection object at 0x7f52f2bf0bf0>: Failed to establish a new connection: [Errno 111] Connection refused'))
unit-vault-k8s-2: 02:42:25 ERROR unit.vault-k8s/2.juju-log [vault_client] Error while checking Vault health status: HTTPSConnectionPool(host='vault-k8s-2.vault-k8s-endpoints.test-kv-tucn.svc.cluster.local', port=8200): Max retries exceeded with url: /v1/sys/health (Caused by NewConnectionError('<urllib3.connection.HTTPSConnection object at 0x7ff6ee1119a0>: Failed to establish a new connection: [Errno 111] Connection refused'))
unit-vault-k8s-1: 02:42:25 ERROR unit.vault-k8s/1.juju-log vault-peers:0: [vault_client] Error while checking Vault health status: HTTPSConnectionPool(host='vault-k8s-1.vault-k8s-endpoints.test-kv-tucn.svc.cluster.local', port=8200): Max retries exceeded with url: /v1/sys/health (Caused by NewConnectionError('<urllib3.connection.HTTPSConnection object at 0x7f0bd02eb140>: Failed to establish a new connection: [Errno 111] Connection refused'))
unit-vault-k8s-2: 02:42:26 ERROR unit.vault-k8s/2.juju-log vault-peers:0: [vault_client] Error while checking Vault health status: HTTPSConnectionPool(host='vault-k8s-2.vault-k8s-endpoints.test-kv-tucn.svc.cluster.local', port=8200): Max retries exceeded with url: /v1/sys/health (Caused by NewConnectionError('<urllib3.connection.HTTPSConnection object at 0x7fc2aa93b0e0>: Failed to establish a new connection: [Errno 111] Connection refused'))
unit-vault-k8s-1: 02:45:01 ERROR juju.worker.dependency "log-sender" manifold worker returned unexpected error: sending log message: write tcp 10.1.63.216:41982->10.152.183.254:17070: write: connection reset by peer: write tcp 10.1.63.216:41982->10.152.183.254:17070: write: connection reset by peer
unit-vault-k8s-0: 02:45:01 ERROR juju.worker.dependency "log-sender" manifold worker returned unexpected error: sending log message: websocket: close 1005 (no status): websocket: close sent
model-7c130367-8ffb-42ef-8c48-9bc25553ef4e: 02:45:01 ERROR juju.worker.dependency "log-sender" manifold worker returned unexpected error: sending log message: websocket: close 1005 (no status): websocket: close sent
unit-vault-k8s-2: 02:45:02 ERROR juju.worker.dependency "log-sender" manifold worker returned unexpected error: sending log message: websocket: close sent

[32mINFO    [0m pytest_operator.plugin:plugin.py:1049 Resetting model test-kv-tucn...
[32mINFO    [0m pytest_operator.plugin:plugin.py:1038    Destroying applications vault-k8s
[32mINFO    [0m pytest_operator.plugin:plugin.py:1038    Destroying applications vault-kv-requirer-a
[32mINFO    [0m pytest_operator.plugin:plugin.py:1038    Destroying applications vault-kv-requirer-b
[32mINFO    [0m pytest_operator.plugin:plugin.py:1054 Not waiting on reset to complete.
[32mINFO    [0m pytest_operator.plugin:plugin.py:1025 Forgetting model main...