[32mINFO    [0m juju.model:__init__.py:3254 Waiting for model:
  vault-k8s/0 [idle] active: 
  vault-k8s/1 [idle] active: 
  vault-k8s/2 [idle] active: 
  loki-k8s/0 [idle] active: 
[32mINFO    [0m juju.model:__init__.py:3254 Waiting for model:
  vault-k8s/0 [idle] active: 
  vault-k8s/1 [idle] active: 
  vault-k8s/2 [idle] active: 
  loki-k8s/0 [executing] active:
[32mINFO    [0m pytest_operator.plugin:plugin.py:937 Model status:

Model          Controller                Cloud/Region        Version  SLA          Timestamp
test-cos-loqm  github-pr-1523e-microk8s  microk8s/localhost  3.6.8    unsupported  02:46:49Z

App             Version  Status  Scale  Charm           Channel   Rev  Address         Exposed  Message
loki-k8s        2.9.6    active      1  loki-k8s        1/stable  199  10.152.183.201  no       
prometheus-k8s  2.52.0   active      1  prometheus-k8s  1/stable  247  10.152.183.35   no       
vault-k8s                active      3  vault-k8s                   0  10.152.183.194  no       

Unit               Workload  Agent  Address      Ports  Message
loki-k8s/0*        active    idle   10.1.63.223         
prometheus-k8s/0*  active    idle   10.1.63.222         
vault-k8s/0*       active    idle   10.1.63.208         
vault-k8s/1        active    idle   10.1.63.216         
vault-k8s/2        active    idle   10.1.63.219         

[32mINFO    [0m pytest_operator.plugin:plugin.py:943 Juju error logs:

unit-vault-k8s-1: 02:43:03 ERROR unit.vault-k8s/1.juju-log [vault_client] Error while checking Vault health status: HTTPSConnectionPool(host='vault-k8s-1.vault-k8s-endpoints.test-cos-loqm.svc.cluster.local', port=8200): Max retries exceeded with url: /v1/sys/health (Caused by NewConnectionError('<urllib3.connection.HTTPSConnection object at 0x7fc551067410>: Failed to establish a new connection: [Errno 111] Connection refused'))
unit-vault-k8s-1: 02:43:04 ERROR unit.vault-k8s/1.juju-log [vault_client] Error while checking Vault health status: HTTPSConnectionPool(host='vault-k8s-1.vault-k8s-endpoints.test-cos-loqm.svc.cluster.local', port=8200): Max retries exceeded with url: /v1/sys/health (Caused by NewConnectionError('<urllib3.connection.HTTPSConnection object at 0x7fae55b3ef00>: Failed to establish a new connection: [Errno 111] Connection refused'))
unit-vault-k8s-2: 02:43:05 ERROR unit.vault-k8s/2.juju-log [vault_client] Error while checking Vault health status: HTTPSConnectionPool(host='vault-k8s-2.vault-k8s-endpoints.test-cos-loqm.svc.cluster.local', port=8200): Max retries exceeded with url: /v1/sys/health (Caused by NewConnectionError('<urllib3.connection.HTTPSConnection object at 0x7f822226f2c0>: Failed to establish a new connection: [Errno 111] Connection refused'))
unit-vault-k8s-1: 02:43:06 ERROR unit.vault-k8s/1.juju-log vault-peers:0: [vault_client] Error while checking Vault health status: HTTPSConnectionPool(host='vault-k8s-1.vault-k8s-endpoints.test-cos-loqm.svc.cluster.local', port=8200): Max retries exceeded with url: /v1/sys/health (Caused by NewConnectionError('<urllib3.connection.HTTPSConnection object at 0x7f9e94962ea0>: Failed to establish a new connection: [Errno 111] Connection refused'))
unit-vault-k8s-2: 02:43:07 ERROR unit.vault-k8s/2.juju-log [vault_client] Error while checking Vault health status: HTTPSConnectionPool(host='vault-k8s-2.vault-k8s-endpoints.test-cos-loqm.svc.cluster.local', port=8200): Max retries exceeded with url: /v1/sys/health (Caused by NewConnectionError('<urllib3.connection.HTTPSConnection object at 0x7f50a613ef00>: Failed to establish a new connection: [Errno 111] Connection refused'))
unit-vault-k8s-2: 02:43:09 ERROR unit.vault-k8s/2.juju-log vault-peers:0: [vault_client] Error while checking Vault health status: HTTPSConnectionPool(host='vault-k8s-2.vault-k8s-endpoints.test-cos-loqm.svc.cluster.local', port=8200): Max retries exceeded with url: /v1/sys/health (Caused by NewConnectionError('<urllib3.connection.HTTPSConnection object at 0x7fcc6a6eb200>: Failed to establish a new connection: [Errno 111] Connection refused'))
unit-prometheus-k8s-0: 02:43:19 ERROR juju.worker.uniter pebble poll failed for container "prometheus": failed to send pebble-ready event: terminated
model-01a565c4-a865-4454-8bb6-e03e6a10cab8: 02:45:08 ERROR juju.worker.dependency "log-sender" manifold worker returned unexpected error: sending log message: websocket: close 1005 (no status): websocket: close sent
unit-vault-k8s-0: 02:45:08 ERROR juju.worker.dependency "log-sender" manifold worker returned unexpected error: sending log message: write tcp 10.1.63.208:50550->10.152.183.118:17070: write: broken pipe: write tcp 10.1.63.208:50550->10.152.183.118:17070: write: broken pipe
unit-vault-k8s-1: 02:45:08 ERROR juju.worker.dependency "log-sender" manifold worker returned unexpected error: sending log message: websocket: close 1005 (no status): websocket: close sent
unit-vault-k8s-2: 02:45:08 ERROR juju.worker.dependency "log-sender" manifold worker returned unexpected error: sending log message: websocket: close 1005 (no status): websocket: close sent

[32mINFO    [0m pytest_operator.plugin:plugin.py:1049 Resetting model test-cos-loqm...
[32mINFO    [0m pytest_operator.plugin:plugin.py:1038    Destroying applications vault-k8s
[32mINFO    [0m pytest_operator.plugin:plugin.py:1038    Destroying applications prometheus-k8s
[32mINFO    [0m pytest_operator.plugin:plugin.py:1038    Destroying applications loki-k8s
[32mINFO    [0m pytest_operator.plugin:plugin.py:1054 Not waiting on reset to complete.
[32mINFO    [0m pytest_operator.plugin:plugin.py:1025 Forgetting model main...