[32mINFO    [0m juju.model:__init__.py:3254 Waiting for model:
  tls-certificates-requirer/0 [executing] active: Certificate relation is created
[32mINFO    [0m juju.model:__init__.py:3254 Waiting for model:
  vault-k8s/0 [executing] active: 
  vault-k8s/1 [executing] active: 
  vault-k8s/2 [executing] active:
[32mINFO    [0m pytest_operator.plugin:plugin.py:951 Model status:

Model          Controller                Cloud/Region        Version  SLA          Timestamp
test-pki-eyhl  github-pr-12038-microk8s  microk8s/localhost  3.6.8    unsupported  04:04:22Z

App                        Version  Status  Scale  Charm                      Channel        Rev  Address         Exposed  Message
self-signed-certificates            active      1  self-signed-certificates   1/stable       317  10.152.183.207  no       
tls-certificates-requirer           active      1  tls-certificates-requirer  latest/stable   93  10.152.183.109  no       Unit certificate is available
vault-k8s                           active      3  vault-k8s                                   0  10.152.183.126  no       

Unit                          Workload  Agent  Address      Ports  Message
self-signed-certificates/0*   active    idle   10.1.63.212         
tls-certificates-requirer/0*  active    idle   10.1.63.216         Unit certificate is available
vault-k8s/0*                  active    idle   10.1.63.208         
vault-k8s/1                   active    idle   10.1.63.217         
vault-k8s/2                   active    idle   10.1.63.218         

[32mINFO    [0m pytest_operator.plugin:plugin.py:957 Juju error logs:

unit-vault-k8s-1: 04:02:31 ERROR unit.vault-k8s/1.juju-log [vault_client] Error while checking Vault health status: HTTPSConnectionPool(host='vault-k8s-1.vault-k8s-endpoints.test-pki-eyhl.svc.cluster.local', port=8200): Max retries exceeded with url: /v1/sys/health (Caused by NewConnectionError('<urllib3.connection.HTTPSConnection object at 0x7fdde83dc110>: Failed to establish a new connection: [Errno 111] Connection refused'))
unit-vault-k8s-1: 04:02:32 ERROR unit.vault-k8s/1.juju-log [vault_client] Error while checking Vault health status: HTTPSConnectionPool(host='vault-k8s-1.vault-k8s-endpoints.test-pki-eyhl.svc.cluster.local', port=8200): Max retries exceeded with url: /v1/sys/health (Caused by NewConnectionError('<urllib3.connection.HTTPSConnection object at 0x7f2e783f3da0>: Failed to establish a new connection: [Errno 111] Connection refused'))
unit-vault-k8s-2: 04:02:33 ERROR unit.vault-k8s/2.juju-log [vault_client] Error while checking Vault health status: HTTPSConnectionPool(host='vault-k8s-2.vault-k8s-endpoints.test-pki-eyhl.svc.cluster.local', port=8200): Max retries exceeded with url: /v1/sys/health (Caused by NewConnectionError('<urllib3.connection.HTTPSConnection object at 0x7f7836f099a0>: Failed to establish a new connection: [Errno 111] Connection refused'))
unit-vault-k8s-1: 04:02:34 ERROR unit.vault-k8s/1.juju-log vault-peers:0: [vault_client] Error while checking Vault health status: HTTPSConnectionPool(host='vault-k8s-1.vault-k8s-endpoints.test-pki-eyhl.svc.cluster.local', port=8200): Max retries exceeded with url: /v1/sys/health (Caused by NewConnectionError('<urllib3.connection.HTTPSConnection object at 0x7f77d37c19a0>: Failed to establish a new connection: [Errno 111] Connection refused'))
unit-vault-k8s-2: 04:02:34 ERROR unit.vault-k8s/2.juju-log [vault_client] Error while checking Vault health status: HTTPSConnectionPool(host='vault-k8s-2.vault-k8s-endpoints.test-pki-eyhl.svc.cluster.local', port=8200): Max retries exceeded with url: /v1/sys/health (Caused by NewConnectionError('<urllib3.connection.HTTPSConnection object at 0x7f1fbb9cbc80>: Failed to establish a new connection: [Errno 111] Connection refused'))
unit-vault-k8s-2: 04:02:35 ERROR unit.vault-k8s/2.juju-log vault-peers:0: [vault_client] Error while checking Vault health status: HTTPSConnectionPool(host='vault-k8s-2.vault-k8s-endpoints.test-pki-eyhl.svc.cluster.local', port=8200): Max retries exceeded with url: /v1/sys/health (Caused by NewConnectionError('<urllib3.connection.HTTPSConnection object at 0x7f3aaa5f3680>: Failed to establish a new connection: [Errno 111] Connection refused'))
unit-self-signed-certificates-0: 04:03:25 ERROR unit.self-signed-certificates/0.juju-log At least 1 matching relation ID not found with the relation name 'send-ca-cert'
unit-self-signed-certificates-0: 04:03:35 ERROR unit.self-signed-certificates/0.juju-log certificates:1: At least 1 matching relation ID not found with the relation name 'send-ca-cert'
unit-self-signed-certificates-0: 04:03:36 ERROR unit.self-signed-certificates/0.juju-log certificates:1: At least 1 matching relation ID not found with the relation name 'send-ca-cert'
unit-self-signed-certificates-0: 04:03:39 ERROR unit.self-signed-certificates/0.juju-log certificates:1: At least 1 matching relation ID not found with the relation name 'send-ca-cert'
unit-self-signed-certificates-0: 04:03:42 ERROR unit.self-signed-certificates/0.juju-log certificates:1: At least 1 matching relation ID not found with the relation name 'send-ca-cert'
unit-self-signed-certificates-0: 04:03:53 ERROR unit.self-signed-certificates/0.juju-log At least 1 matching relation ID not found with the relation name 'send-ca-cert'
unit-self-signed-certificates-0: 04:04:13 ERROR unit.self-signed-certificates/0.juju-log certificates:1: At least 1 matching relation ID not found with the relation name 'send-ca-cert'

[32mINFO    [0m pytest_operator.plugin:plugin.py:1063 Resetting model test-pki-eyhl...
[32mINFO    [0m pytest_operator.plugin:plugin.py:1052    Destroying applications vault-k8s
[32mINFO    [0m pytest_operator.plugin:plugin.py:1052    Destroying applications self-signed-certificates
[32mINFO    [0m pytest_operator.plugin:plugin.py:1052    Destroying applications tls-certificates-requirer
[32mINFO    [0m pytest_operator.plugin:plugin.py:1068 Not waiting on reset to complete.
[32mINFO    [0m pytest_operator.plugin:plugin.py:1039 Forgetting model main...