[32mINFO    [0m juju.model:__init__.py:3254 Waiting for model:
  tls-certificates-requirer/0 [executing] active: Certificate relation is created
[32mINFO    [0m juju.model:__init__.py:3254 Waiting for model:
  vault-k8s/0 [executing] active: 
  vault-k8s/1 [executing] active: 
  vault-k8s/2 [executing] active:
[32mINFO    [0m pytest_operator.plugin:plugin.py:951 Model status:

Model          Controller                Cloud/Region        Version  SLA          Timestamp
test-pki-bw1z  github-pr-0e479-microk8s  microk8s/localhost  3.6.8    unsupported  06:37:38Z

App                        Version  Status  Scale  Charm                      Channel        Rev  Address         Exposed  Message
self-signed-certificates            active      1  self-signed-certificates   1/stable       317  10.152.183.99   no       
tls-certificates-requirer           active      1  tls-certificates-requirer  latest/stable   93  10.152.183.204  no       Unit certificate is available
vault-k8s                           active      3  vault-k8s                                   0  10.152.183.142  no       

Unit                          Workload  Agent  Address      Ports  Message
self-signed-certificates/0*   active    idle   10.1.63.212         
tls-certificates-requirer/0*  active    idle   10.1.63.214         Unit certificate is available
vault-k8s/0*                  active    idle   10.1.63.208         
vault-k8s/1                   active    idle   10.1.63.217         
vault-k8s/2                   active    idle   10.1.63.218         

[32mINFO    [0m pytest_operator.plugin:plugin.py:957 Juju error logs:

unit-vault-k8s-1: 06:35:47 ERROR unit.vault-k8s/1.juju-log [vault_client] Error while checking Vault health status: HTTPSConnectionPool(host='vault-k8s-1.vault-k8s-endpoints.test-pki-bw1z.svc.cluster.local', port=8200): Max retries exceeded with url: /v1/sys/health (Caused by NewConnectionError('<urllib3.connection.HTTPSConnection object at 0x7f1bffa80350>: Failed to establish a new connection: [Errno 111] Connection refused'))
unit-vault-k8s-1: 06:35:48 ERROR unit.vault-k8s/1.juju-log [vault_client] Error while checking Vault health status: HTTPSConnectionPool(host='vault-k8s-1.vault-k8s-endpoints.test-pki-bw1z.svc.cluster.local', port=8200): Max retries exceeded with url: /v1/sys/health (Caused by NewConnectionError('<urllib3.connection.HTTPSConnection object at 0x7faca25ebef0>: Failed to establish a new connection: [Errno 111] Connection refused'))
unit-vault-k8s-2: 06:35:48 ERROR unit.vault-k8s/2.juju-log [vault_client] Error while checking Vault health status: HTTPSConnectionPool(host='vault-k8s-2.vault-k8s-endpoints.test-pki-bw1z.svc.cluster.local', port=8200): Max retries exceeded with url: /v1/sys/health (Caused by NewConnectionError('<urllib3.connection.HTTPSConnection object at 0x7f6daa1f82f0>: Failed to establish a new connection: [Errno 111] Connection refused'))
unit-vault-k8s-1: 06:35:49 ERROR unit.vault-k8s/1.juju-log vault-peers:0: [vault_client] Error while checking Vault health status: HTTPSConnectionPool(host='vault-k8s-1.vault-k8s-endpoints.test-pki-bw1z.svc.cluster.local', port=8200): Max retries exceeded with url: /v1/sys/health (Caused by NewConnectionError('<urllib3.connection.HTTPSConnection object at 0x7f16d8f6fdd0>: Failed to establish a new connection: [Errno 111] Connection refused'))
unit-vault-k8s-2: 06:35:50 ERROR unit.vault-k8s/2.juju-log [vault_client] Error while checking Vault health status: HTTPSConnectionPool(host='vault-k8s-2.vault-k8s-endpoints.test-pki-bw1z.svc.cluster.local', port=8200): Max retries exceeded with url: /v1/sys/health (Caused by NewConnectionError('<urllib3.connection.HTTPSConnection object at 0x7fbd9a7cbe30>: Failed to establish a new connection: [Errno 111] Connection refused'))
unit-vault-k8s-2: 06:35:51 ERROR unit.vault-k8s/2.juju-log vault-peers:0: [vault_client] Error while checking Vault health status: HTTPSConnectionPool(host='vault-k8s-2.vault-k8s-endpoints.test-pki-bw1z.svc.cluster.local', port=8200): Max retries exceeded with url: /v1/sys/health (Caused by NewConnectionError('<urllib3.connection.HTTPSConnection object at 0x7fa2e0208050>: Failed to establish a new connection: [Errno 111] Connection refused'))
unit-self-signed-certificates-0: 06:36:39 ERROR unit.self-signed-certificates/0.juju-log At least 1 matching relation ID not found with the relation name 'send-ca-cert'
unit-self-signed-certificates-0: 06:36:51 ERROR unit.self-signed-certificates/0.juju-log certificates:1: At least 1 matching relation ID not found with the relation name 'send-ca-cert'
unit-self-signed-certificates-0: 06:36:54 ERROR unit.self-signed-certificates/0.juju-log certificates:1: At least 1 matching relation ID not found with the relation name 'send-ca-cert'
unit-self-signed-certificates-0: 06:36:56 ERROR unit.self-signed-certificates/0.juju-log certificates:1: At least 1 matching relation ID not found with the relation name 'send-ca-cert'
unit-self-signed-certificates-0: 06:36:59 ERROR unit.self-signed-certificates/0.juju-log certificates:1: At least 1 matching relation ID not found with the relation name 'send-ca-cert'
unit-self-signed-certificates-0: 06:37:11 ERROR unit.self-signed-certificates/0.juju-log At least 1 matching relation ID not found with the relation name 'send-ca-cert'
unit-self-signed-certificates-0: 06:37:30 ERROR unit.self-signed-certificates/0.juju-log certificates:1: At least 1 matching relation ID not found with the relation name 'send-ca-cert'

[32mINFO    [0m pytest_operator.plugin:plugin.py:1063 Resetting model test-pki-bw1z...
[32mINFO    [0m pytest_operator.plugin:plugin.py:1052    Destroying applications vault-k8s
[32mINFO    [0m pytest_operator.plugin:plugin.py:1052    Destroying applications self-signed-certificates
[32mINFO    [0m pytest_operator.plugin:plugin.py:1052    Destroying applications tls-certificates-requirer
[32mINFO    [0m pytest_operator.plugin:plugin.py:1068 Not waiting on reset to complete.
[32mINFO    [0m pytest_operator.plugin:plugin.py:1039 Forgetting model main...