[32mINFO    [0m juju.model:__init__.py:3254 Waiting for model:
  vault-k8s/0 [idle] active: 
  vault-k8s/1 [idle] active: 
  vault-k8s/2 [idle] active: 
[32mINFO    [0m juju.model:__init__.py:3254 Waiting for model:
  s3-integrator/0 [idle] active:
[32mINFO    [0m pytest_operator.plugin:plugin.py:951 Model status:

Model             Controller                Cloud/Region        Version  SLA          Timestamp
test-backup-gh38  github-pr-a1436-microk8s  microk8s/localhost  3.6.8    unsupported  06:07:45Z

App            Version                Status  Scale  Charm          Channel         Rev  Address         Exposed  Message
minio          res:oci-image@220b31a  active      1  minio          ckf-1.9/stable  383  10.152.183.143  no       
s3-integrator                         active      1  s3-integrator  latest/stable   145  10.152.183.234  no       
vault-k8s                             active      3  vault-k8s                        0  10.152.183.199  no       

Unit              Workload  Agent  Address     Ports          Message
minio/0*          active    idle   10.1.98.28  9000-9001/TCP  
s3-integrator/0*  active    idle   10.1.98.22                 
vault-k8s/0*      active    idle   10.1.98.17                 
vault-k8s/1       active    idle   10.1.98.26                 
vault-k8s/2       active    idle   10.1.98.25                 

[32mINFO    [0m pytest_operator.plugin:plugin.py:957 Juju error logs:

unit-vault-k8s-1: 06:05:04 ERROR unit.vault-k8s/1.juju-log vault-peers:0: [vault_client] Error while checking Vault health status: HTTPSConnectionPool(host='vault-k8s-1.vault-k8s-endpoints.test-backup-gh38.svc.cluster.local', port=8200): Max retries exceeded with url: /v1/sys/health (Caused by NewConnectionError('<urllib3.connection.HTTPSConnection object at 0x7f857bdf2630>: Failed to establish a new connection: [Errno 111] Connection refused'))
unit-vault-k8s-2: 06:05:06 ERROR unit.vault-k8s/2.juju-log [vault_client] Error while checking Vault health status: HTTPSConnectionPool(host='vault-k8s-2.vault-k8s-endpoints.test-backup-gh38.svc.cluster.local', port=8200): Max retries exceeded with url: /v1/sys/health (Caused by NewConnectionError('<urllib3.connection.HTTPSConnection object at 0x7f6d7947cec0>: Failed to establish a new connection: [Errno 111] Connection refused'))
unit-vault-k8s-1: 06:05:06 ERROR unit.vault-k8s/1.juju-log [vault_client] Error while checking Vault health status: HTTPSConnectionPool(host='vault-k8s-1.vault-k8s-endpoints.test-backup-gh38.svc.cluster.local', port=8200): Max retries exceeded with url: /v1/sys/health (Caused by NewConnectionError('<urllib3.connection.HTTPSConnection object at 0x7ff4b9a10680>: Failed to establish a new connection: [Errno 111] Connection refused'))
unit-vault-k8s-2: 06:05:07 ERROR unit.vault-k8s/2.juju-log [vault_client] Error while checking Vault health status: HTTPSConnectionPool(host='vault-k8s-2.vault-k8s-endpoints.test-backup-gh38.svc.cluster.local', port=8200): Max retries exceeded with url: /v1/sys/health (Caused by NewConnectionError('<urllib3.connection.HTTPSConnection object at 0x7efc47b7ca10>: Failed to establish a new connection: [Errno 111] Connection refused'))
unit-vault-k8s-1: 06:05:07 ERROR unit.vault-k8s/1.juju-log [vault_client] Error while checking Vault health status: HTTPSConnectionPool(host='vault-k8s-1.vault-k8s-endpoints.test-backup-gh38.svc.cluster.local', port=8200): Max retries exceeded with url: /v1/sys/health (Caused by NewConnectionError('<urllib3.connection.HTTPSConnection object at 0x7fdc11610fb0>: Failed to establish a new connection: [Errno 111] Connection refused'))
unit-vault-k8s-2: 06:05:09 ERROR unit.vault-k8s/2.juju-log vault-peers:0: [vault_client] Error while checking Vault health status: HTTPSConnectionPool(host='vault-k8s-2.vault-k8s-endpoints.test-backup-gh38.svc.cluster.local', port=8200): Max retries exceeded with url: /v1/sys/health (Caused by NewConnectionError('<urllib3.connection.HTTPSConnection object at 0x7f23f8584aa0>: Failed to establish a new connection: [Errno 111] Connection refused'))
unit-vault-k8s-1: 06:05:09 ERROR unit.vault-k8s/1.juju-log [vault_client] Error while checking Vault health status: HTTPSConnectionPool(host='vault-k8s-1.vault-k8s-endpoints.test-backup-gh38.svc.cluster.local', port=8200): Max retries exceeded with url: /v1/sys/health (Caused by NewConnectionError('<urllib3.connection.HTTPSConnection object at 0x7fec59100e60>: Failed to establish a new connection: [Errno 111] Connection refused'))
unit-vault-k8s-1: 06:05:10 ERROR unit.vault-k8s/1.juju-log [vault_client] Error while checking Vault health status: HTTPSConnectionPool(host='vault-k8s-1.vault-k8s-endpoints.test-backup-gh38.svc.cluster.local', port=8200): Max retries exceeded with url: /v1/sys/health (Caused by NewConnectionError('<urllib3.connection.HTTPSConnection object at 0x7f3bf2208e90>: Failed to establish a new connection: [Errno 111] Connection refused'))

[32mINFO    [0m pytest_operator.plugin:plugin.py:1063 Resetting model test-backup-gh38...
[32mINFO    [0m pytest_operator.plugin:plugin.py:1052    Destroying applications vault-k8s
[32mINFO    [0m pytest_operator.plugin:plugin.py:1052    Destroying applications s3-integrator
[32mINFO    [0m pytest_operator.plugin:plugin.py:1052    Destroying applications minio
[32mINFO    [0m pytest_operator.plugin:plugin.py:1068 Not waiting on reset to complete.
[32mINFO    [0m pytest_operator.plugin:plugin.py:1039 Forgetting model main...