[32mINFO    [0m juju.model:__init__.py:3254 Waiting for model:
  vault-k8s/0 [executing] active: 
  vault-k8s/1 [executing] active: 
  vault-k8s/2 [executing] active: 
[32mINFO    [0m juju.model:__init__.py:3254 Waiting for model:
  tls-certificates-requirer/0 [executing] active: Certificate relation is created
[32mINFO    [0m pytest_operator.plugin:plugin.py:951 Model status:

Model          Controller                Cloud/Region        Version  SLA          Timestamp
test-pki-f23o  github-pr-c1a48-microk8s  microk8s/localhost  3.6.8    unsupported  08:52:49Z

App                        Version  Status  Scale  Charm                      Channel        Rev  Address         Exposed  Message
self-signed-certificates            active      1  self-signed-certificates   1/stable       317  10.152.183.230  no       
tls-certificates-requirer           active      1  tls-certificates-requirer  latest/stable   93  10.152.183.184  no       Unit certificate is available
vault-k8s                           active      3  vault-k8s                                   0  10.152.183.90   no       

Unit                          Workload  Agent  Address      Ports  Message
self-signed-certificates/0*   active    idle   10.1.63.212         
tls-certificates-requirer/0*  active    idle   10.1.63.216         Unit certificate is available
vault-k8s/0*                  active    idle   10.1.63.209         
vault-k8s/1                   active    idle   10.1.63.217         
vault-k8s/2                   active    idle   10.1.63.218         

[32mINFO    [0m pytest_operator.plugin:plugin.py:957 Juju error logs:

unit-vault-k8s-1: 08:50:56 ERROR unit.vault-k8s/1.juju-log [vault_client] Error while checking Vault health status: HTTPSConnectionPool(host='vault-k8s-1.vault-k8s-endpoints.test-pki-f23o.svc.cluster.local', port=8200): Max retries exceeded with url: /v1/sys/health (Caused by NewConnectionError('<urllib3.connection.HTTPSConnection object at 0x7f6f32b05c40>: Failed to establish a new connection: [Errno 111] Connection refused'))
unit-vault-k8s-2: 08:50:56 ERROR unit.vault-k8s/2.juju-log [vault_client] Error while checking Vault health status: HTTPSConnectionPool(host='vault-k8s-2.vault-k8s-endpoints.test-pki-f23o.svc.cluster.local', port=8200): Max retries exceeded with url: /v1/sys/health (Caused by NewConnectionError('<urllib3.connection.HTTPSConnection object at 0x7f6c93df82f0>: Failed to establish a new connection: [Errno 111] Connection refused'))
unit-vault-k8s-1: 08:50:57 ERROR unit.vault-k8s/1.juju-log [vault_client] Error while checking Vault health status: HTTPSConnectionPool(host='vault-k8s-1.vault-k8s-endpoints.test-pki-f23o.svc.cluster.local', port=8200): Max retries exceeded with url: /v1/sys/health (Caused by NewConnectionError('<urllib3.connection.HTTPSConnection object at 0x7f1b4b77f9e0>: Failed to establish a new connection: [Errno 111] Connection refused'))
unit-vault-k8s-2: 08:50:57 ERROR unit.vault-k8s/2.juju-log [vault_client] Error while checking Vault health status: HTTPSConnectionPool(host='vault-k8s-2.vault-k8s-endpoints.test-pki-f23o.svc.cluster.local', port=8200): Max retries exceeded with url: /v1/sys/health (Caused by NewConnectionError('<urllib3.connection.HTTPSConnection object at 0x7f65c2e03a70>: Failed to establish a new connection: [Errno 111] Connection refused'))
unit-vault-k8s-1: 08:50:58 ERROR unit.vault-k8s/1.juju-log vault-peers:0: [vault_client] Error while checking Vault health status: HTTPSConnectionPool(host='vault-k8s-1.vault-k8s-endpoints.test-pki-f23o.svc.cluster.local', port=8200): Max retries exceeded with url: /v1/sys/health (Caused by NewConnectionError('<urllib3.connection.HTTPSConnection object at 0x7f8a5820c0e0>: Failed to establish a new connection: [Errno 111] Connection refused'))
unit-vault-k8s-2: 08:50:59 ERROR unit.vault-k8s/2.juju-log vault-peers:0: [vault_client] Error while checking Vault health status: HTTPSConnectionPool(host='vault-k8s-2.vault-k8s-endpoints.test-pki-f23o.svc.cluster.local', port=8200): Max retries exceeded with url: /v1/sys/health (Caused by NewConnectionError('<urllib3.connection.HTTPSConnection object at 0x7f489d3d1c10>: Failed to establish a new connection: [Errno 111] Connection refused'))
unit-self-signed-certificates-0: 08:51:50 ERROR unit.self-signed-certificates/0.juju-log At least 1 matching relation ID not found with the relation name 'send-ca-cert'
unit-self-signed-certificates-0: 08:52:02 ERROR unit.self-signed-certificates/0.juju-log certificates:1: At least 1 matching relation ID not found with the relation name 'send-ca-cert'
unit-self-signed-certificates-0: 08:52:05 ERROR unit.self-signed-certificates/0.juju-log certificates:1: At least 1 matching relation ID not found with the relation name 'send-ca-cert'
unit-self-signed-certificates-0: 08:52:06 ERROR unit.self-signed-certificates/0.juju-log certificates:1: At least 1 matching relation ID not found with the relation name 'send-ca-cert'
unit-self-signed-certificates-0: 08:52:09 ERROR unit.self-signed-certificates/0.juju-log certificates:1: At least 1 matching relation ID not found with the relation name 'send-ca-cert'
unit-self-signed-certificates-0: 08:52:18 ERROR unit.self-signed-certificates/0.juju-log At least 1 matching relation ID not found with the relation name 'send-ca-cert'
unit-self-signed-certificates-0: 08:52:40 ERROR unit.self-signed-certificates/0.juju-log certificates:1: At least 1 matching relation ID not found with the relation name 'send-ca-cert'

[32mINFO    [0m pytest_operator.plugin:plugin.py:1063 Resetting model test-pki-f23o...
[32mINFO    [0m pytest_operator.plugin:plugin.py:1052    Destroying applications vault-k8s
[32mINFO    [0m pytest_operator.plugin:plugin.py:1052    Destroying applications self-signed-certificates
[32mINFO    [0m pytest_operator.plugin:plugin.py:1052    Destroying applications tls-certificates-requirer
[32mINFO    [0m pytest_operator.plugin:plugin.py:1068 Not waiting on reset to complete.
[32mINFO    [0m pytest_operator.plugin:plugin.py:1039 Forgetting model main...