[32mINFO    [0m juju.model:__init__.py:2301 Deploying local:vault-kv-requirer-1
[32mINFO    [0m juju.model:__init__.py:3254 Waiting for model:
  vault-kv-requirer-b/0 [allocating] waiting: installing agent
[32mINFO    [0m juju.model:__init__.py:3254 Waiting for model:
  vault-kv-requirer-b/0 [idle] active: 
[32mINFO    [0m juju.model:__init__.py:3254 Waiting for model:
  vault-k8s/0 [idle] active: 
  vault-k8s/1 [idle] active: 
  vault-k8s/2 [idle] active: 
  vault-kv-requirer-b/0 [idle] active: 
[32mINFO    [0m juju.model:__init__.py:3254 Waiting for model:
  vault-kv-requirer-b/0 [idle] active:
[32mINFO    [0m pytest_operator.plugin:plugin.py:951 Model status:

Model         Controller                Cloud/Region        Version  SLA          Timestamp
test-kv-xi8q  github-pr-c1a48-microk8s  microk8s/localhost  3.6.8    unsupported  08:53:57Z

App                  Version  Status  Scale  Charm              Channel  Rev  Address         Exposed  Message
vault-k8s                     active      3  vault-k8s                     0  10.152.183.25   no       
vault-kv-requirer-a           active      1  vault-kv-requirer             0  10.152.183.99   no       
vault-kv-requirer-b           active      1  vault-kv-requirer             1  10.152.183.144  no       

Unit                    Workload  Agent  Address      Ports  Message
vault-k8s/0*            active    idle   10.1.63.208         
vault-k8s/1             active    idle   10.1.63.216         
vault-k8s/2             active    idle   10.1.63.217         
vault-kv-requirer-a/0*  active    idle   10.1.63.219         
vault-kv-requirer-b/0*  active    idle   10.1.63.221         

[32mINFO    [0m pytest_operator.plugin:plugin.py:957 Juju error logs:

unit-vault-k8s-1: 08:49:59 ERROR unit.vault-k8s/1.juju-log [vault_client] Error while checking Vault health status: HTTPSConnectionPool(host='vault-k8s-1.vault-k8s-endpoints.test-kv-xi8q.svc.cluster.local', port=8200): Max retries exceeded with url: /v1/sys/health (Caused by NewConnectionError('<urllib3.connection.HTTPSConnection object at 0x7f335b329a00>: Failed to establish a new connection: [Errno 111] Connection refused'))
unit-vault-k8s-2: 08:50:00 ERROR unit.vault-k8s/2.juju-log [vault_client] Error while checking Vault health status: HTTPSConnectionPool(host='vault-k8s-2.vault-k8s-endpoints.test-kv-xi8q.svc.cluster.local', port=8200): Max retries exceeded with url: /v1/sys/health (Caused by NewConnectionError('<urllib3.connection.HTTPSConnection object at 0x7fcda58e1070>: Failed to establish a new connection: [Errno 111] Connection refused'))
unit-vault-k8s-1: 08:50:01 ERROR unit.vault-k8s/1.juju-log [vault_client] Error while checking Vault health status: HTTPSConnectionPool(host='vault-k8s-1.vault-k8s-endpoints.test-kv-xi8q.svc.cluster.local', port=8200): Max retries exceeded with url: /v1/sys/health (Caused by NewConnectionError('<urllib3.connection.HTTPSConnection object at 0x7f3124be7c50>: Failed to establish a new connection: [Errno 111] Connection refused'))
unit-vault-k8s-2: 08:50:02 ERROR unit.vault-k8s/2.juju-log [vault_client] Error while checking Vault health status: HTTPSConnectionPool(host='vault-k8s-2.vault-k8s-endpoints.test-kv-xi8q.svc.cluster.local', port=8200): Max retries exceeded with url: /v1/sys/health (Caused by NewConnectionError('<urllib3.connection.HTTPSConnection object at 0x7f86aa5ebbf0>: Failed to establish a new connection: [Errno 111] Connection refused'))
unit-vault-k8s-1: 08:50:02 ERROR unit.vault-k8s/1.juju-log vault-peers:0: [vault_client] Error while checking Vault health status: HTTPSConnectionPool(host='vault-k8s-1.vault-k8s-endpoints.test-kv-xi8q.svc.cluster.local', port=8200): Max retries exceeded with url: /v1/sys/health (Caused by NewConnectionError('<urllib3.connection.HTTPSConnection object at 0x7fa24e40c080>: Failed to establish a new connection: [Errno 111] Connection refused'))
unit-vault-k8s-2: 08:50:03 ERROR unit.vault-k8s/2.juju-log vault-peers:0: [vault_client] Error while checking Vault health status: HTTPSConnectionPool(host='vault-k8s-2.vault-k8s-endpoints.test-kv-xi8q.svc.cluster.local', port=8200): Max retries exceeded with url: /v1/sys/health (Caused by NewConnectionError('<urllib3.connection.HTTPSConnection object at 0x7f7498b5fec0>: Failed to establish a new connection: [Errno 111] Connection refused'))
unit-vault-k8s-1: 08:52:40 ERROR juju.worker.dependency "log-sender" manifold worker returned unexpected error: sending log message: websocket: close 1005 (no status): websocket: close sent
model-1340a4a6-d03f-4dcb-885b-83834747fe27: 08:52:40 ERROR juju.worker.dependency "log-sender" manifold worker returned unexpected error: sending log message: websocket: close 1005 (no status): websocket: close sent
unit-vault-k8s-0: 08:52:42 ERROR juju.worker.dependency "log-sender" manifold worker returned unexpected error: sending log message: write tcp 10.1.63.208:38108->10.152.183.28:17070: write: connection reset by peer: write tcp 10.1.63.208:38108->10.152.183.28:17070: write: connection reset by peer
unit-vault-k8s-2: 08:53:00 ERROR juju.worker.dependency "log-sender" manifold worker returned unexpected error: sending log message: websocket: close 1005 (no status): websocket: close sent
unit-vault-k8s-1: 08:53:22 ERROR juju.worker.dependency "log-sender" manifold worker returned unexpected error: sending log message: websocket: close 1005 (no status): websocket: close sent
model-1340a4a6-d03f-4dcb-885b-83834747fe27: 08:53:22 ERROR juju.worker.dependency "log-sender" manifold worker returned unexpected error: sending log message: websocket: close 1005 (no status): websocket: close sent
unit-vault-k8s-0: 08:53:22 ERROR juju.worker.dependency "log-sender" manifold worker returned unexpected error: sending log message: websocket: close 1005 (no status): websocket: close sent

[32mINFO    [0m pytest_operator.plugin:plugin.py:1063 Resetting model test-kv-xi8q...
[32mINFO    [0m pytest_operator.plugin:plugin.py:1052    Destroying applications vault-k8s
[32mINFO    [0m pytest_operator.plugin:plugin.py:1052    Destroying applications vault-kv-requirer-a
[32mINFO    [0m pytest_operator.plugin:plugin.py:1052    Destroying applications vault-kv-requirer-b
[32mINFO    [0m pytest_operator.plugin:plugin.py:1068 Not waiting on reset to complete.
[32mINFO    [0m pytest_operator.plugin:plugin.py:1039 Forgetting model main...