[32mINFO    [0m juju.model:__init__.py:2301 Deploying local:vault-kv-requirer-1
[32mINFO    [0m juju.model:__init__.py:3254 Waiting for model:
  vault-kv-requirer-b/0 [allocating] waiting: installing agent
[32mINFO    [0m juju.model:__init__.py:3254 Waiting for model:
  vault-kv-requirer-b/0 [idle] active: 
[32mINFO    [0m juju.model:__init__.py:3254 Waiting for model:
  vault-k8s/0 [idle] active: 
  vault-k8s/1 [idle] active: 
  vault-k8s/2 [idle] active: 
  vault-kv-requirer-b/0 [idle] active: 
[32mINFO    [0m juju.model:__init__.py:3254 Waiting for model:
  vault-kv-requirer-b/0 [idle] active:
[32mINFO    [0m pytest_operator.plugin:plugin.py:951 Model status:

Model         Controller                Cloud/Region        Version  SLA          Timestamp
test-kv-5n11  github-pr-a06eb-microk8s  microk8s/localhost  3.6.8    unsupported  02:00:36Z

App                  Version  Status  Scale  Charm              Channel  Rev  Address         Exposed  Message
vault-k8s                     active      3  vault-k8s                     0  10.152.183.40   no       
vault-kv-requirer-a           active      1  vault-kv-requirer             0  10.152.183.86   no       
vault-kv-requirer-b           active      1  vault-kv-requirer             1  10.152.183.164  no       

Unit                    Workload  Agent  Address     Ports  Message
vault-k8s/0*            active    idle   10.1.98.17         
vault-k8s/1             active    idle   10.1.98.24         
vault-k8s/2             active    idle   10.1.98.25         
vault-kv-requirer-a/0*  active    idle   10.1.98.27         
vault-kv-requirer-b/0*  active    idle   10.1.98.29         

[32mINFO    [0m pytest_operator.plugin:plugin.py:957 Juju error logs:

unit-vault-k8s-1: 01:56:45 ERROR unit.vault-k8s/1.juju-log [vault_client] Error while checking Vault health status: HTTPSConnectionPool(host='vault-k8s-1.vault-k8s-endpoints.test-kv-5n11.svc.cluster.local', port=8200): Max retries exceeded with url: /v1/sys/health (Caused by NewConnectionError('<urllib3.connection.HTTPSConnection object at 0x7f1b50719280>: Failed to establish a new connection: [Errno 111] Connection refused'))
unit-vault-k8s-2: 01:56:46 ERROR unit.vault-k8s/2.juju-log [vault_client] Error while checking Vault health status: HTTPSConnectionPool(host='vault-k8s-2.vault-k8s-endpoints.test-kv-5n11.svc.cluster.local', port=8200): Max retries exceeded with url: /v1/sys/health (Caused by NewConnectionError('<urllib3.connection.HTTPSConnection object at 0x7efd1916cc50>: Failed to establish a new connection: [Errno 111] Connection refused'))
unit-vault-k8s-1: 01:56:47 ERROR unit.vault-k8s/1.juju-log [vault_client] Error while checking Vault health status: HTTPSConnectionPool(host='vault-k8s-1.vault-k8s-endpoints.test-kv-5n11.svc.cluster.local', port=8200): Max retries exceeded with url: /v1/sys/health (Caused by NewConnectionError('<urllib3.connection.HTTPSConnection object at 0x7f3b471809e0>: Failed to establish a new connection: [Errno 111] Connection refused'))
unit-vault-k8s-2: 01:56:48 ERROR unit.vault-k8s/2.juju-log [vault_client] Error while checking Vault health status: HTTPSConnectionPool(host='vault-k8s-2.vault-k8s-endpoints.test-kv-5n11.svc.cluster.local', port=8200): Max retries exceeded with url: /v1/sys/health (Caused by NewConnectionError('<urllib3.connection.HTTPSConnection object at 0x7f904f37c860>: Failed to establish a new connection: [Errno 111] Connection refused'))
unit-vault-k8s-1: 01:56:48 ERROR unit.vault-k8s/1.juju-log vault-peers:0: [vault_client] Error while checking Vault health status: HTTPSConnectionPool(host='vault-k8s-1.vault-k8s-endpoints.test-kv-5n11.svc.cluster.local', port=8200): Max retries exceeded with url: /v1/sys/health (Caused by NewConnectionError('<urllib3.connection.HTTPSConnection object at 0x7fa27d184ad0>: Failed to establish a new connection: [Errno 111] Connection refused'))
unit-vault-k8s-2: 01:56:49 ERROR unit.vault-k8s/2.juju-log vault-peers:0: [vault_client] Error while checking Vault health status: HTTPSConnectionPool(host='vault-k8s-2.vault-k8s-endpoints.test-kv-5n11.svc.cluster.local', port=8200): Max retries exceeded with url: /v1/sys/health (Caused by NewConnectionError('<urllib3.connection.HTTPSConnection object at 0x7f5671e189e0>: Failed to establish a new connection: [Errno 111] Connection refused'))
unit-vault-k8s-2: 01:59:20 ERROR juju.worker.dependency "log-sender" manifold worker returned unexpected error: sending log message: websocket: close 1005 (no status): websocket: close sent
unit-vault-k8s-0: 01:59:20 ERROR juju.worker.dependency "log-sender" manifold worker returned unexpected error: sending log message: websocket: close 1005 (no status): websocket: close sent
model-284d91e9-1cdf-4c3a-850c-52463fb42a48: 01:59:21 ERROR juju.worker.dependency "log-sender" manifold worker returned unexpected error: sending log message: websocket: close 1005 (no status): websocket: close sent
unit-vault-k8s-1: 01:59:23 ERROR juju.worker.dependency "log-sender" manifold worker returned unexpected error: sending log message: write tcp 10.1.98.24:59880->10.152.183.116:17070: write: connection reset by peer: write tcp 10.1.98.24:59880->10.152.183.116:17070: write: connection reset by peer

[32mINFO    [0m pytest_operator.plugin:plugin.py:1063 Resetting model test-kv-5n11...
[32mINFO    [0m pytest_operator.plugin:plugin.py:1052    Destroying applications vault-k8s
[32mINFO    [0m pytest_operator.plugin:plugin.py:1052    Destroying applications vault-kv-requirer-a
[32mINFO    [0m pytest_operator.plugin:plugin.py:1052    Destroying applications vault-kv-requirer-b
[32mINFO    [0m pytest_operator.plugin:plugin.py:1068 Not waiting on reset to complete.
[32mINFO    [0m pytest_operator.plugin:plugin.py:1039 Forgetting model main...